Workbook

Sheet CMIG4
A1: | | B1: Feito | C1: 46058 | D1: Atual | E1: 46247 | F1: Não | G1: 46058 | H1: Não | I1: 46058 | J1: Ultimo_Balanco | K1: {=IFERROR(INDEX(Indicador_Ações[], MATCH($J$2, Indicador_Ações[Stock], 0), MATCH(Indicador_Ações[[#HEADERS],[ult_balanco_processado]], Indicador_Ações[#HEADERS], 0)),"")} -> 46203
A2: Balanço Patrimonial Anual | J2: CMIG4 | K2: =IFERROR(__xludf.DUMMYFUNCTION("(GOOGLEFINANCE(""BVMF:"" & J2))"),11.28) -> 11.28 | L2: {=IFERROR(INDEX(Indicador_Ações[], MATCH($J$2, Indicador_Ações[Stock], 0), MATCH(Indicador_Ações[[#HEADERS],[qtd_acao]], Indicador_Ações[#HEADERS], 0)),"")} -> 2861780000 | M2: Numero_Papel
A3: Ano | B3: 1_T | C3: AH% (2/1) | D3: 2_T | E3: AH% (3/2) | F3: 3_T | G3: AH% (4/3) | H3: 4_T | J3: BP | K3: 1000 | L3: =IFERROR(K22/K14,0) -> 0.089136821 | M3: Margem_Liquida_Ajustada | N3: DMPL Acumulado
A4: Ativo Total | B4: =B5+B6 -> 68174293 | C4: =IFERROR(SUM((D4/B4)-1),0) -> 0.039413038 | D4: =D5+D6 -> 70861249 | E4: =IFERROR(SUM((F4/D4)-1),0) -> -0.08624045 | F4: =F5+F6 -> 64750143 | G4: =IFERROR(SUM((H4/F4)-1),0) -> 0.035180355 | H4: =H5+H6 -> 67028076 | J4: Ativo | K4: {=IFERROR(INDEX(Indicador_Ações[], MATCH($J$2, Indicador_Ações[Stock], 0), MATCH(Indicador_Ações[[#HEADERS],[ativo]], Indicador_Ações[#HEADERS], 0)),"")} -> 70861300000 | L4: =IFERROR(K19/K14,0) -> 0.16436566 | M4: MARGEM BRUTA | N4: JCP acionistas Liquido | O4: 657957
A5: Ativo Circulante | B5: 14417420 | C5: =IFERROR(SUM((D5/B5)-1),0) -> 0.090381289 | D5: 15720485 | E5: =IFERROR(SUM((F5/D5)-1),0) -> -0.15736951 | F5: 13246560 | G5: =IFERROR(SUM((H5/F5)-1),0) -> 0.093097982 | H5: 14479788 | J5: Valor_de_mercado | K5: =K2*L2 -> 32280878400 | L5: =IFERROR(K16/K14,0) -> 0.13740098 | M5: MARGEM EBIT | N5: Dividendos | O5: 0
A6: Ativo Nao Circ. | B6: 53756873 | C6: =IFERROR(SUM((D6/B6)-1),0) -> 0.025743517 | D6: 55140764 | E6: =IFERROR(SUM((F6/D6)-1),0) -> -0.065961745 | F6: 51503583 | G6: =IFERROR(SUM((H6/F6)-1),0) -> 0.020284123 | H6: 52548288 | J6: Valor_da_firma | K6: =SUM(K5,K10) -> 51551468400 | L6: =IFERROR(K17/K14,0) -> 0.19372224 | M6: MARGEM_EBITDA_Ajustada | N6: Dividendos e JCP | O6: =SUM(O4:O5) -> 657957
J7: Disponibilidade | K7: {=IFERROR(INDEX(Indicador_Ações[], MATCH($J$2, Indicador_Ações[Stock], 0), MATCH(Indicador_Ações[[#HEADERS],[disponibilidades]], Indicador_Ações[#HEADERS], 0)),"")} -> 3082110000 | L7: =K22/L2 -> 1.3623689 | M7: LPA_Ajustado | N7: Aliquota | O7: =ABS(SUM(B67,D67,F67,H67)/SUM(B66,D66,F66,H66)) -> 0.10938791
A8: Estoque | B8: 0 | C8: =IFERROR(SUM((D8/B8)-1),0) -> 0 | D8: 0 | E8: =IFERROR(SUM((F8/D8)-1),0) -> 0 | F8: 0 | G8: =IFERROR(SUM((H8/F8)-1),0) -> 0 | H8: 0 | J8: Patrimônio líq | K8: {=IFERROR(INDEX(Indicador_Ações[], MATCH($J$2, Indicador_Ações[Stock], 0), MATCH(Indicador_Ações[[#HEADERS],[patrimonio_liquido]], Indicador_Ações[#HEADERS], 0)),"")} -> 29181600000 | L8: {=IFERROR(INDEX(O6*K3,0)/L2,"")} -> 0.2299118 | M8: DPA Liquido | N8: NOPAT | O8: =K16*(1-O7) -> 5352445083
A9: Caixa | B9: 1377560 | C9: =IFERROR(SUM((D9/B9)-1),0) -> 0.56972909 | D9: 2162396 | E9: =IFERROR(SUM((F9/D9)-1),0) -> -0.32866875 | F9: 1451684 | G9: =IFERROR(SUM((H9/F9)-1),0) -> 0.30995175 | H9: 1901636 | J9: Dívida bruta | K9: {=IFERROR(INDEX(Indicador_Ações[], MATCH($J$2, Indicador_Ações[Stock], 0), MATCH(Indicador_Ações[[#HEADERS],[divida_bruta]], Indicador_Ações[#HEADERS], 0)),"")} -> 22352700000 | L9: =IFERROR(L8/L7,0) -> 0.16875885 | M9: Payout_Ajustado
A10: Títulos e valores mobiliários | B10: 414962 | C10: =IFERROR(SUM((D10/B10)-1),0) -> 1.2163788 | D10: 919713 | E10: =IFERROR(SUM((F10/D10)-1),0) -> -0.059098871 | F10: 865359 | G10: =IFERROR(SUM((H10/F10)-1),0) -> -0.12209615 | H10: 759702 | J10: Dívida líq | K10: =K9-K7 -> 19270590000 | L10: =IFERROR(K14/K4,0) -> 0.61725512 | M10: GIRO ATIVOS
A11: Disponibilidades | B11: =SUM(B9,B10) -> 1792522 | C11: =IFERROR(SUM((D11/B11)-1),0) -> 0.71942604 | D11: =SUM(D9,D10) -> 3082109 | E11: =IFERROR(SUM((F11/D11)-1),0) -> -0.24822808 | F11: =SUM(F9,F10) -> 2317043 | G11: =IFERROR(SUM((H11/F11)-1),0) -> 0.14859241 | H11: =SUM(H9,H10) -> 2661338 | J11: Capital_Investido | K11: =SUM(K8,K9) -> 51534300000 | L11: =IFERROR(K22/K8,0) -> 0.13360474 | M11: ROE
J12: Razão de Divida | K12: =K9/K11 -> 0.43374413 | L12: =O8/K11 -> 0.1038618 | M12: ROIC
A13: Passivo Total | B13: =SUM(B14+B15) -> 39280917 | C13: =IFERROR(SUM((D13/B13)-1),0) -> 0.060950181 | D13: =SUM(D14+D15) -> 41675096 | E13: =IFERROR(SUM((F13/D13)-1),0) -> -0.13580321 | F13: =SUM(F14+F15) -> 36015484 | G13: =IFERROR(SUM((H13/F13)-1),0) -> 0.067495664 | H13: =SUM(H14+H15) -> 38446373 | J13: DRE | L13: =IFERROR(K22/K4,0) -> 0.055020159 | M13: ROA
A14: Passivo Circ. | B14: 15478646 | C14: =IFERROR(SUM((D14/B14)-1),0) -> -0.13019511 | D14: 13463402 | E14: =IFERROR(SUM((F14/D14)-1),0) -> 0.10548693 | F14: 14883615 | G14: =IFERROR(SUM((H14/F14)-1),0) -> -0.02829353 | H14: 14462505 | J14: Receita_Liquida | K14: {=IFERROR(INDEX(Indicador_Ações[], MATCH($J$2, Indicador_Ações[Stock], 0), MATCH(Indicador_Ações[[#HEADERS],[receita_liquida_12m]], Indicador_Ações[#HEADERS], 0)),"")} -> 43739500000 | L14: =K6/K17 -> 6.0839795 | M14: EV/EBITDA
A15: Passivo Não Circ. | B15: 23802271 | C15: =IFERROR(SUM((D15/B15)-1),0) -> 0.1852522 | D15: 28211694 | E15: =IFERROR(SUM((F15/D15)-1),0) -> -0.25095356 | F15: 21131869 | G15: =IFERROR(SUM((H15/F15)-1),0) -> 0.13496199 | H15: 23983868 | J15: Cagr_receita_5a | K15: {=IFERROR(INDEX(Indicador_Ações[], MATCH($J$2, Indicador_Ações[Stock], 0), MATCH(Indicador_Ações[[#HEADERS],[cagr_receita_5a]], Indicador_Ações[#HEADERS], 0)),"")} -> 6.1 | L15: =K17/K6 -> 0.1643661 | M15: Earnings_Yield_Greenblatt
A16: Emprést. CP | B16: 3083137 | C16: =IFERROR(SUM((D16/B16)-1),0) -> -0.5072616 | D16: 1519180 | E16: =IFERROR(SUM((F16/D16)-1),0) -> 0.96314525 | F16: 2982371 | G16: =IFERROR(SUM((H16/F16)-1),0) -> 0.023227157 | H16: 3051643 | J16: EBIT | K16: {=IFERROR(INDEX(Indicador_Ações[], MATCH($J$2, Indicador_Ações[Stock], 0), MATCH(Indicador_Ações[[#HEADERS],[ebit_12m]], Indicador_Ações[#HEADERS], 0)),"")} -> 6009850000 | L16: =IFERROR(K10/K17,0) -> 2.2742684 | M16: DÍVIDA LÍQUIDA / EBITDA Ajustado
A17: Emprést. LP | B17: 16527380 | C17: =IFERROR(SUM((D17/B17)-1),0) -> 0.26054638 | D17: 20833529 | E17: =IFERROR(SUM((F17/D17)-1),0) -> -0.40341274 | F17: 12429018 | G17: =IFERROR(SUM((H17/F17)-1),0) -> 0.32059411 | H17: 16413688 | J17: EBITDA Ajustado | K17: =SUM(B70,D70,F70,H70)*K3 -> 8473314000 | L17: =IFERROR(SUM(B5,D5,F5,H5)/SUM(B14,D14,F14,H14),0) -> 0.99272725 | M17: LIQUIDEZ CORRENTE_Media
J18: Custo_Mercadoria | K18: =SUM(B33,D33,F33,H33)*1000 -> -36550266000 | L18: =IFERROR(SUM(B58,D58,F58,H58)/ABS(SUM(B61,D61,F61,H61)),0) -> 2.4898526 | M18: Indice de Cobertura de Juros MEDIA
A19: ENDIVIDAMENTO / CAIXA | J19: Lucro bruto | K19: =IFERROR(SUM(B44,D44,F44,H44),"")*1000 -> 7189272000 | L19: =IFERROR(K4/K8,0) -> 2.428287 | M19: Alavancagem_Financeira
A20: Dívida bruta | B20: =SUM(B17,B16) -> 19610517 | C20: =IFERROR(SUM((D20/B20)-1),0) -> 0.13983272 | D20: =SUM(D17,D16) -> 22352709 | E20: =IFERROR(SUM((F20/D20)-1),0) -> -0.31053596 | F20: =SUM(F17,F16) -> 15411389 | G20: =IFERROR(SUM((H20/F20)-1),0) -> 0.26304845 | H20: =SUM(H17,H16) -> 19465331 | J20: Despesas operacionais | K20: =IFERROR(SUM(B55,D55,F55,H55),"")*1000 -> -551913000 | L20: =K10/K8 -> 0.66036783 | M20: DL/PL
A21: Dívida líq | B21: =SUM(B20-B11) -> 17817995 | C21: =IFERROR(SUM((D21/B21)-1),0) -> 0.081524605 | D21: =SUM(D20-D11) -> 19270600 | E21: =IFERROR(SUM((F21/D21)-1),0) -> -0.32050139 | F21: =SUM(F20-F11) -> 13094346 | G21: =IFERROR(SUM((H21/F21)-1),0) -> 0.28330143 | H21: =SUM(H20-H11) -> 16803993 | J21: Inflação | K21: ='Indicadores_Ações'!$B$4 -> 0.044430246 | M21: CPM
J22: Lucro_Anual_Ajustado | K22: =SUM(B71,D71,F71,H71)*1000000 -> 3898800000 | L22: ='Indicadores_Ações'!$B$3 -> 0.139 | M22: RF
A23: Patrimônio líq. | B23: =B4-B13 -> 28893376 | C23: =IFERROR(SUM((D23/B23)-1),0) -> 0.010133015 | D23: =D4-D13 -> 29186153 | E23: =IFERROR(SUM((F23/D23)-1),0) -> -0.015469459 | F23: =F4-F13 -> 28734659 | G23: =IFERROR(SUM((H23/F23)-1),0) -> -0.0053230491 | H23: =H4-H13 -> 28581703 | J23: Lucro_Liquido_Fundamentus | K23: {=IFERROR(INDEX(Indicador_Ações[], MATCH($J$2, Indicador_Ações[Stock], 0), MATCH(Indicador_Ações[[#HEADERS],[lucro_liquido_12m]], Indicador_Ações[#HEADERS], 0)),"")} -> 4595100000 | L23: =K24 -> 0.91 | M23: Beta (B)
J24: Beta | K24: {=IFERROR(INDEX(Indicador_Ações[], MATCH($J$2, Indicador_Ações[Stock], 0), MATCH(Indicador_Ações[[#HEADERS],[beta_ibov_3a]], Indicador_Ações[#HEADERS], 0)),"")} -> 0.91 | L24: =L22+0.02 -> 0.159 | M24: RM
A25: Reserva de Capital | B25: 393093 | C25: =IFERROR(SUM((D25/B25)-1),0) -> 0 | D25: 393093 | E25: =IFERROR(SUM((F25/D25)-1),0) -> 0 | F25: 393093 | G25: =IFERROR(SUM((H25/F25)-1),0) -> 0 | H25: 393093 | L25: =L22+L23*(L24-L22) -> 0.1572 | M25: KE
A26: Reserva de Lucro | B26: 14217595 | C26: =IFERROR(SUM((D26/B26)-1),0) -> 0 | D26: 14217595 | E26: =IFERROR(SUM((F26/D26)-1),0) -> -0.045151589 | F26: 13575648 | G26: =IFERROR(SUM((H26/F26)-1),0) -> 0.047286656 | H26: 14217595
A27: Lucro ou Prejuizo Acumulados | B27: 323712 | C27: =IFERROR(SUM((D27/B27)-1),0) -> 0.97121207 | D27: 638105 | E27: =IFERROR(SUM((F27/D27)-1),0) -> 1.0206126 | F27: 1289363 | G27: =IFERROR(SUM((H27/F27)-1),0) -> -1 | H27: 0 | J27: Ticker | K27: Valores | L27: Ano | M27: VLF | N27: VLP | O27: Cresc
J28: Preço_Mercado | K28: =K2 -> 11.28 | L28: 1 | M28: =K33 -> 3898800000 | O28: 5 | Q28: Ano | R28: Fluxo
A29: DRE Analise Trimestral | J29: Numero_Papel | K29: =L2 -> 2861780000 | L29: 2 | M29: =M28*(1+O28/100) -> 4093740000 | N29: =M29/(1+K34)^L28 -> 3537625302 | O29: 5 | Q29: 0 | R29: =-K6 -> -51551468400
A30: Trimestre | B30: 1_T | C30: AH% (2/1) | D30: 2_T | E30: AH% (3/2) | F30: 3_T | G30: AH% (4/3) | H30: 4_T | J30: Market | K30: =K5 -> 32280878400 | L30: 3 | M30: =M29*(1+O29/100) -> 4298427000 | N30: =M30/(1+K34)^L29 -> 3209908890 | O30: 5 | Q30: 1 | R30: =M29 -> 4093740000
A31: Receita Bruta | J31: Taxa_Cresc | K31: =SUM(O28:O36)/6 -> 5 | L31: 4 | M31: =M30*(1+O30/100) -> 4513348350 | N31: =M31/(1+K34)^L30 -> 2912551274 | O31: 5 | Q31: 2 | R31: =M30 -> 4298427000
A32: Receita Liquida | B32: 10462543 | C32: =IFERROR(SUM((D32/B32)-1),0) -> 0.066302714 | D32: 11156238 | E32: =IFERROR(SUM((F32/D32)-1),0) -> -0.048089419 | F32: 10619741 | G32: =IFERROR(SUM((H32/F32)-1),0) -> 0.082984604 | H32: 11501016 | J32: Taxa_Gordon | K32: 0.04 | L32: 5 | M32: =M31*(1+O31/100) -> 4739015768 | N32: =M32/(1+K34)^L31 -> 2642740095 | O32: 5 | Q32: 3 | R32: =M31 -> 4513348350
A33: Custo Mercadoria (CMV) | B33: =SUM(B34,B38,B39) -> -8737422 | C33: =IFERROR(SUM((D33/B33)-1),0) -> 0.040539875 | D33: =SUM(D34,D38,D39) -> -9091636 | E33: =IFERROR(SUM((F33/D33)-1),0) -> 0.0030407069 | F33: =SUM(F34,F38,F39) -> -9119281 | G33: =IFERROR(SUM((H33/F33)-1),0) -> 0.052925883 | H33: =SUM(H34,H38,H39) -> -9601927 | J33: Lucro_Ajustado_Planilha | K33: =$K$22 -> 3898800000 | L33: 6 | M33: =M32*(1+O32/100) -> 4975966556 | N33: =M33/(1+K34)^L32 -> 2397923522 | O33: 5 | Q33: 4 | R33: =M32 -> 4739015768
A34: Custos com energia elétrica e gás | B34: =SUM(B35:B37) -> -5846956 | C34: =IFERROR(SUM((D34/B34)-1),0) -> -0.0055957322 | D34: =SUM(D35:D37) -> -5814238 | E34: =IFERROR(SUM((F34/D34)-1),0) -> 0.061192026 | F34: =SUM(F35:F37) -> -6170023 | G34: =IFERROR(SUM((H34/F34)-1),0) -> 0.0014259266 | H34: =SUM(H35:H37) -> -6178821 | J34: Taxa_desconto_KE | K34: =L25 -> 0.1572 | L34: 7 | M34: =M33*(1+O33/100) -> 5224764884 | N34: =M34/(1+K34)^L33 -> 2175786120 | Q34: 5 | R34: =M33 -> 4975966556
A35: Energia elétrica comprada para revenda | B35: -4915028 | C35: =IFERROR(SUM((D35/B35)-1),0) -> -0.026402901 | D35: -4785257 | E35: =IFERROR(SUM((F35/D35)-1),0) -> 0.078952917 | F35: -5163067 | G35: =IFERROR(SUM((H35/F35)-1),0) -> 0.0073446655 | H35: -5200988 | J35: Valor_ação_Proj | K35: =K36/K29 -> 11.727333 | L35: Perpétuo | M35: =IFERROR( M34 * (1 + K32) / (K34 -K32 ), 0 ) -> 46363101357 | N35: =M35/(1+K34)^L34 -> 16684511845 | Q35: 6 | R35: =M34+M35 -> 51587866240
A36: Encargos de uso da rede básica | B36: -718658 | C36: =IFERROR(SUM((D36/B36)-1),0) -> 0.15563453 | D36: -830506 | E36: =IFERROR(SUM((F36/D36)-1),0) -> -0.077615333 | F36: -766046 | G36: =IFERROR(SUM((H36/F36)-1),0) -> -0.020126729 | H36: -750628 | J36: Market_Proj | K36: =N36 -> 33561047049 | N36: =SUM(N28:N35) -> 33561047049 | Q36: TIR | R36: =IFERROR(IRR(R29:R35),0) -> 0.075215283
A37: Gás comprado para revenda | B37: -213270 | C37: =IFERROR(SUM((D37/B37)-1),0) -> -0.069372157 | D37: -198475 | E37: =IFERROR(SUM((F37/D37)-1),0) -> 0.21380527 | F37: -240910 | G37: =IFERROR(SUM((H37/F37)-1),0) -> -0.056888465 | H37: -227205
A38: Custos de construção de infraestrutura | B38: -1482436 | C38: =IFERROR(SUM((D38/B38)-1),0) -> 0.18257382 | D38: -1753090 | E38: =IFERROR(SUM((F38/D38)-1),0) -> -0.086132486 | F38: -1602092 | G38: =IFERROR(SUM((H38/F38)-1),0) -> 0.14575755 | H38: -1835609
A39: Custos de operação | B39: =SUM(B40:B43) -> -1408030 | C39: =IFERROR(SUM((D39/B39)-1),0) -> 0.082582047 | D39: =SUM(D40:D43) -> -1524308 | E39: =IFERROR(SUM((F39/D39)-1),0) -> -0.11621142 | F39: =SUM(F40:F43) -> -1347166 | G39: =IFERROR(SUM((H39/F39)-1),0) -> 0.17839747 | H39: =SUM(H40:H43) -> -1587497
A40: Pessoal (reversões) | B40: -365592 | C40: =IFERROR(SUM((D40/B40)-1),0) -> 0.15102902 | D40: -420807 | E40: =IFERROR(SUM((F40/D40)-1),0) -> -0.19866827 | F40: -337206 | G40: =IFERROR(SUM((H40/F40)-1),0) -> 0.1314597 | H40: -381535
...

Sheet TAEE11
B1: Feito | C1: 46058 | D1: Atual | E1: 46245 | F1: Não | G1: 46058 | H1: Não | I1: 46058 | J1: Ultimo_Balanco | K1: {=IFERROR(INDEX(Indicador_Ações[], MATCH($J$2, Indicador_Ações[Stock], 0), MATCH(Indicador_Ações[[#HEADERS],[ult_balanco_processado]], Indicador_Ações[#HEADERS], 0)),"")} -> 46203
A2: Balanço Patrimonial Anual | J2: TAEE11 | K2: =IFERROR(__xludf.DUMMYFUNCTION("(GOOGLEFINANCE(""BVMF:"" & J2))"),40.99) -> 40.99 | L2: {=IFERROR(INDEX(Indicador_Ações[], MATCH($J$2, Indicador_Ações[Stock], 0), MATCH(Indicador_Ações[[#HEADERS],[qtd_acao]], Indicador_Ações[#HEADERS], 0)),"")/3} -> 344500000 | M2: Numero_Papel
A3: Ano | B3: 1_T | C3: AH% (2/1) | D3: 2_T | E3: AH% (3/2) | F3: 3_T | G3: AH% (4/3) | H3: 4_T | J3: BP | K3: 1000 | L3: =IFERROR(K23/K15,0) -> 0.39398172 | M3: MARGEM LÍQUIDA | N3: DMPL Acumulado
A4: Ativo Total | B4: =B5+B6 -> 14173294 | C4: =IFERROR(SUM((D4/B4)-1),0) -> -0.071774776 | D4: =D5+D6 -> 13156009 | E4: =IFERROR(SUM((F4/D4)-1),0) -> -0.0033959387 | F4: =F5+F6 -> 13111332 | G4: =IFERROR(SUM((H4/F4)-1),0) -> 0.040110417 | H4: =H5+H6 -> 13637233 | J4: Ativo | K4: {=IFERROR(INDEX(Indicador_Ações[], MATCH($J$2, Indicador_Ações[Stock], 0), MATCH(Indicador_Ações[[#HEADERS],[ativo]], Indicador_Ações[#HEADERS], 0)),"")} -> 22700900000 | L4: =IFERROR(K20/K15,0) -> 0.64439464 | M4: MARGEM BRUTA | N4: JCP acionistas Liquido | O4: 192574
A5: Ativo Circulante | B5: 2148240 | C5: =IFERROR(SUM((D5/B5)-1),0) -> -0.48169059 | D5: 1113453 | E5: =IFERROR(SUM((F5/D5)-1),0) -> 0.60106174 | F5: 1782707 | G5: =IFERROR(SUM((H5/F5)-1),0) -> 0.053283013 | H5: 1877695 | J5: Valor_de_mercado | K5: =K2*L2 -> 14121055000 | L5: =IFERROR(K17/K15,0) -> 0.79629558 | M5: MARGEM EBIT | N5: Dividendos | O5: 260226
A6: Ativo Nao Circ. | B6: 12025054 | C6: =IFERROR(SUM((D6/B6)-1),0) -> 0.0014554612 | D6: 12042556 | E6: =IFERROR(SUM((F6/D6)-1),0) -> -0.059284009 | F6: 11328625 | G6: =IFERROR(SUM((H6/F6)-1),0) -> 0.038037538 | H6: 11759538 | J6: Valor_da_firma | K6: =SUM(K5,K10) -> 24534795000 | L6: =IFERROR(K18/K15,0) -> 0.84157113 | M6: MARGEM EBITDA | N6: Dividendos remanescentes | O6: 0
J7: Disponibilidade | K7: {=IFERROR(INDEX(Indicador_Ações[], MATCH($J$2, Indicador_Ações[Stock], 0), MATCH(Indicador_Ações[[#HEADERS],[disponibilidades]], Indicador_Ações[#HEADERS], 0)),"")} -> 544160000 | L7: =K23/L2 -> 3.0064499 | M7: LPA | N7: Dividendos e JCP | O7: =SUM(O4:O6) -> 452800
A8: Estoque | B8: 23030 | C8: =IFERROR(SUM((D8/B8)-1),0) -> -0.014155449 | D8: 22704 | E8: =IFERROR(SUM((F8/D8)-1),0) -> -0.69256519 | F8: 6980 | G8: =IFERROR(SUM((H8/F8)-1),0) -> 1.9524355 | H8: 20608 | J8: Patrimônio líq | K8: {=IFERROR(INDEX(Indicador_Ações[], MATCH($J$2, Indicador_Ações[Stock], 0), MATCH(Indicador_Ações[[#HEADERS],[patrimonio_liquido]], Indicador_Ações[#HEADERS], 0)),"")} -> 8070920000 | L8: {=IFERROR(INDEX(O7*K3,0)/L2,"")} -> 1.3143687 | M8: DPA Liquido | N8: Aliquota | O8: =ABS(SUM(B47,D47,F47,H47)/SUM(B46,D46,F46,H46)) -> 0.08728999
A9: Caixa | B9: 1091121 | C9: =IFERROR(SUM((D9/B9)-1),0) -> -0.80904134 | D9: 208359 | E9: =IFERROR(SUM((F9/D9)-1),0) -> 1.9271834 | F9: 609905 | G9: =IFERROR(SUM((H9/F9)-1),0) -> 0.21592051 | H9: 741596 | J9: Dívida bruta | K9: {=IFERROR(INDEX(Indicador_Ações[], MATCH($J$2, Indicador_Ações[Stock], 0), MATCH(Indicador_Ações[[#HEADERS],[divida_bruta]], Indicador_Ações[#HEADERS], 0)),"")} -> 10957900000 | L9: =IFERROR(L8/L7,0) -> 0.43718295 | M9: Payout_Ajustado | N9: NOPAT | O9: =K17*(1-O8) -> 1910619675
A10: Títulos e valores mobiliários | B10: 512539 | C10: =IFERROR(SUM((D10/B10)-1),0) -> -0.34482839 | D10: 335801 | E10: =IFERROR(SUM((F10/D10)-1),0) -> 0.37968321 | F10: 463299 | G10: =IFERROR(SUM((H10/F10)-1),0) -> 0.17451149 | H10: 544150 | J10: Dívida líq | K10: =K9-K7 -> 10413740000 | L10: =IFERROR(K14/K4,0) -> 0.19754283 | M10: GIRO ATIVOS
A11: Disponibilidades | B11: =SUM(B9,B10) -> 1603660 | C11: =IFERROR(SUM((D11/B11)-1),0) -> -0.6606762 | D11: =SUM(D9,D10) -> 544160 | E11: =IFERROR(SUM((F11/D11)-1),0) -> 0.97222141 | F11: =SUM(F9,F10) -> 1073204 | G11: =IFERROR(SUM((H11/F11)-1),0) -> 0.19804436 | H11: =SUM(H9,H10) -> 1285746 | J11: Capital_Investido | K11: =SUM(K8,K9) -> 19028820000 | L11: =IFERROR(K24/K8,0) -> 0.20139835 | M11: ROE
J12: Razão de Divida | K12: =K9/K11 -> 0.57585809 | L12: =O9/K11 -> 0.10040663 | M12: ROIC
A13: Passivo Total | B13: =SUM(B14+B15) -> 12906356 | C13: =IFERROR(SUM((D13/B13)-1),0) -> -0.059554145 | D13: =SUM(D14+D15) -> 12137729 | E13: =IFERROR(SUM((F13/D13)-1),0) -> -0.015778158 | F13: =SUM(F14+F15) -> 11946218 | G13: =IFERROR(SUM((H13/F13)-1),0) -> 0.051332899 | H13: =SUM(H14+H15) -> 12559452 | J13: DRE | L13: =IFERROR(K24/K4,0) -> 0.071603769 | M13: ROA
A14: Passivo Circ. | B14: 1669914 | C14: =IFERROR(SUM((D14/B14)-1),0) -> -0.5010755 | D14: 833161 | E14: =IFERROR(SUM((F14/D14)-1),0) -> 1.4281573 | F14: 2023046 | G14: =IFERROR(SUM((H14/F14)-1),0) -> 0.12095227 | H14: 2267738 | J14: Receita_IFRS | K14: {=IFERROR(INDEX(Indicador_Ações[], MATCH($J$2, Indicador_Ações[Stock], 0), MATCH(Indicador_Ações[[#HEADERS],[receita_liquida_12m]], Indicador_Ações[#HEADERS], 0)),"")} -> 4484400000 | L14: =K6/K18 -> 11.089819 | M14: EV/EBITDA
A15: Passivo Não Circ. | B15: 11236442 | C15: =IFERROR(SUM((D15/B15)-1),0) -> 0.0060629512 | D15: 11304568 | E15: =IFERROR(SUM((F15/D15)-1),0) -> -0.12219804 | F15: 9923172 | G15: =IFERROR(SUM((H15/F15)-1),0) -> 0.037139536 | H15: 10291714 | J15: Receita REG | K15: =IFERROR(SUM(B33,D33,F33,H33),"")*K3 -> 2628858000 | L15: =K18/K6 -> 0.090172793 | M15: Earnings_Yield_Greenblatt
A16: Emprést. CP | B16: 1083543 | C16: =IFERROR(SUM((D16/B16)-1),0) -> -0.8291586 | D16: 185114 | E16: =IFERROR(SUM((F16/D16)-1),0) -> 4.7919282 | F16: 1072167 | G16: =IFERROR(SUM((H16/F16)-1),0) -> 0.25012428 | H16: 1340342 | J16: Cagr_receita_5a | K16: {=IFERROR(INDEX(Indicador_Ações[], MATCH($J$2, Indicador_Ações[Stock], 0), MATCH(Indicador_Ações[[#HEADERS],[cagr_receita_5a]], Indicador_Ações[#HEADERS], 0)),"")} -> 13 | L16: =IFERROR(K10/K18,0) -> 4.7070496 | M16: DÍVIDA LÍQUIDA / EBITDA
A17: Emprést. LP | B17: 10598903 | C17: =IFERROR(SUM((D17/B17)-1),0) -> 0.016330275 | D17: 10771986 | E17: =IFERROR(SUM((F17/D17)-1),0) -> -0.1444702 | F17: 9215755 | G17: =IFERROR(SUM((H17/F17)-1),0) -> 0.045327919 | H17: 9633486 | J17: EBIT Reg | K17: =SUM(B39,D39,F39,H39)*K3 -> 2093348000 | L17: =IFERROR(SUM(B5,D5,F5,H5)/SUM(B14,D14,F14,H14),0) -> 1.0188753 | M17: LIQUIDEZ CORRENTE
J18: EBITDA Reg | K18: =IFERROR(SUM(B45,D45,F45,H45),"")*K3 -> 2212371000 | L18: =SUM(B39,D39,F39,H39)/ABS(SUM(B42,D42,F42,H42)) -> 1.6186636 | M18: Indice de Cobertura de Juros MEDIA
A19: ENDIVIDAMENTO / CAIXA | J19: Custo_Mercadoria | K19: =SUM(B32,D32,F32,H32)*K3 -> -284037000 | L19: =IFERROR(K4/K8,0) -> 2.8126781 | M19: Alavancagem_Financeira
A20: Dívida bruta | B20: =SUM(B17,B16) -> 11682446 | C20: =IFERROR(SUM((D20/B20)-1),0) -> -0.062088539 | D20: =SUM(D17,D16) -> 10957100 | E20: =IFERROR(SUM((F20/D20)-1),0) -> -0.061072547 | F20: =SUM(F17,F16) -> 10287922 | G20: =IFERROR(SUM((H20/F20)-1),0) -> 0.066670995 | H20: =SUM(H17,H16) -> 10973828 | J20: Lucro bruto | K20: =IFERROR(SUM(B36,D36,F36,H36),"")*K3 -> 1694022000 | L20: =K10/K8 -> 1.2902792 | M20: DL/PL
A21: Dívida líq | B21: =SUM(B20-B11) -> 10078786 | C21: =IFERROR(SUM((D21/B21)-1),0) -> 0.033154191 | D21: =SUM(D20-D11) -> 10412940 | E21: =IFERROR(SUM((F21/D21)-1),0) -> -0.11507048 | F21: =SUM(F20-F11) -> 9214718 | G21: =IFERROR(SUM((H21/F21)-1),0) -> 0.051370427 | H21: =SUM(H20-H11) -> 9688082 | J21: Despesas operacionais REG | K21: =IFERROR(SUM(B34,D34,F34,H34),"")*K3 -> -416487000 | M21: CPM
J22: Inflação | K22: ='Indicadores_Ações'!$B$4 -> 0.044430246 | L22: ='Indicadores_Ações'!$B$3 -> 0.139 | M22: RF
A23: Patrimônio líq. | B23: =B4-B13 -> 1266938 | C23: =IFERROR(SUM((D23/B23)-1),0) -> -0.1962669 | D23: =D4-D13 -> 1018280 | E23: =IFERROR(SUM((F23/D23)-1),0) -> 0.14419806 | F23: =F4-F13 -> 1165114 | G23: =IFERROR(SUM((H23/F23)-1),0) -> -0.074956614 | H23: =H4-H13 -> 1077781 | J23: Lucro_Anual REG_Planilha | K23: =SUM(B48,D48,F48,H48)*K3 -> 1035722000 | L23: =K25 -> 0.71 | M23: Beta (B)
J24: Lucro_Liquido_Fundamentus | K24: {=IFERROR(INDEX(Indicador_Ações[], MATCH($J$2, Indicador_Ações[Stock], 0), MATCH(Indicador_Ações[[#HEADERS],[lucro_liquido_12m]], Indicador_Ações[#HEADERS], 0)),"")} -> 1625470000 | L24: =L22+0.01 -> 0.149 | M24: RM
A25: Reserva de Capital | B25: 594507 | C25: =IFERROR(SUM((D25/B25)-1),0) -> 0 | D25: 594507 | E25: =IFERROR(SUM((F25/D25)-1),0) -> 0 | F25: 594507 | G25: =IFERROR(SUM((H25/F25)-1),0) -> 0 | H25: 594507 | J25: Beta | K25: {=IFERROR(INDEX(Indicador_Ações[], MATCH($J$2, Indicador_Ações[Stock], 0), MATCH(Indicador_Ações[[#HEADERS],[beta_ibov_3a]], Indicador_Ações[#HEADERS], 0)),"")} -> 0.71 | L25: =L22+L23*(L24-L22) -> 0.1461 | M25: KE
A26: Reserva de Lucro | B26: 3784357 | C26: =IFERROR(SUM((D26/B26)-1),0) -> -0.021781507 | D26: 3701928 | E26: =IFERROR(SUM((F26/D26)-1),0) -> -0.10085636 | F26: 3328565 | G26: =IFERROR(SUM((H26/F26)-1),0) -> 0.13693348 | H26: 3784357
A27: Lucro ou Prejuizo Acumulados | B27: -6526972 | C27: =IFERROR(SUM((D27/B27)-1),0) -> 0 | D27: -6526972 | E27: =IFERROR(SUM((F27/D27)-1),0) -> -0.069832228 | F27: -6071179 | G27: =IFERROR(SUM((H27/F27)-1),0) -> 0.075074874 | H27: -6526972
J28: Ticker | K28: Valores | L28: Ano | M28: VLF | N28: VLP | O28: Cresc | Q28: Ano | R28: Fluxo
A29: DRE Analise Trimestral | J29: Preço_Mercado | K29: =K2 -> 40.99 | L29: 1 | M29: =K34 -> 1035722000 | O29: 8 | Q29: 0 | R29: =-K6 -> -24534795000
A30: Trimestre | B30: 1_T | C30: AH% (2/1) | D30: 2_T | E30: AH% (3/2) | F30: 3_T | G30: AH% (4/3) | H30: 4_T | J30: Numero_Papel | K30: =L2 -> 344500000 | L30: 2 | M30: =M29*(1+O29/100) -> 1118579760 | N30: =M30/(1+K35)^L29 -> 9.7598792e+08 | O30: 8 | Q30: 1 | R30: =M30 -> 1118579760
A31: Receita Operacional Bruta | B31: 722684 | C31: =IFERROR(SUM((D31/B31)-1),0) -> 0.038560422 | D31: 750551 | E31: =IFERROR(SUM((F31/D31)-1),0) -> -0.036224054 | F31: 723363 | G31: =IFERROR(SUM((H31/F31)-1),0) -> -0.009768263 | H31: 716297 | J31: Market | K31: =P21 | L31: 3 | M31: =M30*(1+O30/100) -> 1208066141 | N31: =M31/(1+K35)^L30 -> 9.1969894e+08 | O31: 8 | Q31: 2 | R31: =M31 -> 1208066141
A32: Deduções da receita Bruta | B32: -67152 | C32: =IFERROR(SUM((D32/B32)-1),0) -> 0.062976531 | D32: -71381 | E32: =IFERROR(SUM((F32/D32)-1),0) -> 0.021168098 | F32: -72892 | G32: =IFERROR(SUM((H32/F32)-1),0) -> -0.0038412995 | H32: -72612 | J32: Taxa_Cresc | K32: =SUM(O29:O37)/6 -> 8 | L32: 4 | M32: =M31*(1+O31/100) -> 1304711432 | N32: =M32/(1+K35)^L31 -> 8.6665636e+08 | O32: 8 | Q32: 3 | R32: =M32 -> 1304711432
A33: Receita Operacional Liquida | B33: =SUM(B31,B32) -> 655532 | C33: =IFERROR(SUM((D33/B33)-1),0) -> 0.036059262 | D33: =SUM(D31,D32) -> 679170 | E33: =IFERROR(SUM((F33/D33)-1),0) -> -0.042255989 | F33: =SUM(F31,F32) -> 650471 | G33: =IFERROR(SUM((H33/F33)-1),0) -> -0.01043244 | H33: =SUM(H31,H32) -> 643685 | J33: Taxa_Gordon | K33: 0.04 | L33: 5 | M33: =M32*(1+O32/100) -> 1409088347 | N33: =M33/(1+K35)^L32 -> 8.1667295e+08 | O33: 8 | Q33: 4 | R33: =M33 -> 1409088347
A34: Custos e Despesas | B34: -93403 | C34: =IFERROR(SUM((D34/B34)-1),0) -> 0.092170487 | D34: -102012 | E34: =IFERROR(SUM((F34/D34)-1),0) -> -0.0031662942 | F34: -101689 | G34: =IFERROR(SUM((H34/F34)-1),0) -> 0.17400112 | H34: -119383 | J34: Receita_LL_REG | K34: =$K$23 -> 1035722000 | L34: 6 | M34: =M33*(1+O33/100) -> 1521815414 | N34: =M34/(1+K35)^L33 -> 7.6957228e+08 | O34: 8 | Q34: 5 | R34: =M34 -> 1521815414
A35: Depreciações e Amortizações | B35: -128467 | C35: =IFERROR(SUM((D35/B35)-1),0) -> -0.0047483011 | D35: -127857 | E35: =IFERROR(SUM((F35/D35)-1),0) -> 0.027069304 | F35: -131318 | G35: =IFERROR(SUM((H35/F35)-1),0) -> -0.0046528275 | H35: -130707 | J35: Taxa_desconto_KE | K35: =L25 -> 0.1461 | L35: 7 | M35: =M34*(1+O34/100) -> 1643560648 | N35: =M35/(1+K35)^L34 -> 7.2518808e+08 | Q35: 6 | R35: =M35+M36 -> 17753862942
A36: Lucro Operacional Bruto | B36: =B33+B34+B35 -> 433662 | C36: =IFERROR(SUM((D36/B36)-1),0) -> 0.036062648 | D36: =D33+D34+D35 -> 449301 | E36: =IFERROR(SUM((F36/D36)-1),0) -> -0.070858956 | F36: =F33+F34+F35 -> 417464 | G36: =IFERROR(SUM((H36/F36)-1),0) -> -0.057176188 | H36: =H33+H34+H35 -> 393595 | J36: Valor_ação_Proj | K36: =K37/K30 -> 32.731441 | L36: Perpétuo | M36: =IFERROR( M35 * (1 + K33) / (K35 -K33 ), 0 ) -> 16110302294 | N36: =M36/(1+K35)^L35 -> 6202204788 | Q36: TIR | R36: =IFERROR(IRR(R29:R35),0) -> -0.0017091351
J37: Market_Proj | K37: =N37 -> 11275981336 | N37: =SUM(N29:N36) -> 11275981336
A38: Resultado de equivalência patrimonial | B38: 90423 | C38: =IFERROR(SUM((D38/B38)-1),0) -> 0.0046669542 | D38: 90845 | E38: =IFERROR(SUM((F38/D38)-1),0) -> 0.17244758 | F38: 106511 | G38: =IFERROR(SUM((H38/F38)-1),0) -> 0.047281501 | H38: 111547
A39: Lucro Operacional (EBIT)(LAJIR) | B39: =SUM(B36,B38) -> 524085 | C39: =IFERROR(SUM((D39/B39)-1),0) -> 0.030645792 | D39: =SUM(D36,D38) -> 540146 | E39: =IFERROR(SUM((F39/D39)-1),0) -> -0.029938202 | F39: =SUM(F36,F38) -> 523975 | G39: =IFERROR(SUM((H39/F39)-1),0) -> -0.035942555 | H39: =SUM(H36,H38) -> 505142
A41: Receita Financeira | B41: 34240 | C41: =IFERROR(SUM((D41/B41)-1),0) -> 0.076372664 | D41: 36855 | E41: =IFERROR(SUM((F41/D41)-1),0) -> 0.21978022 | F41: 44955 | G41: =IFERROR(SUM((H41/F41)-1),0) -> -0.18961183 | H41: 36431
...

Sheet ISAE4
B1: Feito | C1: 46058 | D1: Atual | E1: 46237 | F1: Não | G1: 46058 | H1: Não | I1: 46058 | J1: Ultimo_Balanco | K1: {=IFERROR(INDEX(Indicador_Ações[], MATCH($J$2, Indicador_Ações[Stock], 0), MATCH(Indicador_Ações[[#HEADERS],[ult_balanco_processado]], Indicador_Ações[#HEADERS], 0)),"")} -> 46203
A2: Balanço Patrimonial Anual | J2: ISAE4 | K2: =IFERROR(__xludf.DUMMYFUNCTION("(GOOGLEFINANCE(""BVMF:"" & J2))"),27.74) -> 27.74 | L2: {=IFERROR(INDEX(Indicador_Ações[], MATCH($J$2, Indicador_Ações[Stock], 0), MATCH(Indicador_Ações[[#HEADERS],[qtd_acao]], Indicador_Ações[#HEADERS], 0)),"")} -> 703328000 | M2: Numero_Papel
A3: Ano | B3: 1_T | C3: AH% (2/1) | D3: 2_T | E3: AH% (3/2) | F3: 3_T | G3: AH% (4/3) | H3: 4_T | J3: BP | K3: 1000 | L3: =IFERROR(K23/K15,0) -> 0.34823637 | M3: MARGEM LÍQUIDA | N3: DMPL Acumulado
A4: Ativo Total | B4: =B5+B6 -> 30704682 | C4: =IFERROR(SUM((D4/B4)-1),0) -> 0.041641662 | D4: =D5+D6 -> 31983276 | E4: =IFERROR(SUM((F4/D4)-1),0) -> -0.086219842 | F4: =F5+F6 -> 29225683 | G4: =IFERROR(SUM((H4/F4)-1),0) -> 0.039946748 | H4: =H5+H6 -> 30393154 | J4: Ativo | K4: {=IFERROR(INDEX(Indicador_Ações[], MATCH($J$2, Indicador_Ações[Stock], 0), MATCH(Indicador_Ações[[#HEADERS],[ativo]], Indicador_Ações[#HEADERS], 0)),"")} -> 49954800000 | L4: =IFERROR(K20/K15,0) -> 0.67030512 | M4: MARGEM BRUTA | N4: JCP acionistas Liquido | O4: 279322
A5: Ativo Circulante | B5: 2420425 | C5: =IFERROR(SUM((D5/B5)-1),0) -> 0.19946538 | D5: 2903216 | E5: =IFERROR(SUM((F5/D5)-1),0) -> 0.25989144 | F5: 3657737 | G5: =IFERROR(SUM((H5/F5)-1),0) -> -0.11223224 | H5: 3247221 | J5: Valor_de_mercado | K5: =K2*L2 -> 19510318720 | L5: =IFERROR(K17/K15,0) -> 0.29077953 | M5: MARGEM EBIT | N5: JCP acionistas Liquido 2 | O5: 0
A6: Ativo Nao Circ. | B6: 28284257 | C6: =IFERROR(SUM((D6/B6)-1),0) -> 0.028135899 | D6: 29080060 | E6: =IFERROR(SUM((F6/D6)-1),0) -> -0.12077396 | F6: 25567946 | G6: =IFERROR(SUM((H6/F6)-1),0) -> 0.061717394 | H6: 27145933 | J6: Valor_da_firma | K6: =SUM(K5,K10) -> 35478758720 | L6: =IFERROR(K18/K15,0) -> 0.80006764 | M6: MARGEM EBITDA | N6: Dividendos | O6: 2357
J7: Disponibilidade | K7: {=IFERROR(INDEX(Indicador_Ações[], MATCH($J$2, Indicador_Ações[Stock], 0), MATCH(Indicador_Ações[[#HEADERS],[disponibilidades]], Indicador_Ações[#HEADERS], 0)),"")} -> 1757260000 | L7: =K23/L2 -> 2.3086696 | M7: LPA | N7: Dividendos e JCP | O7: =SUM(O4:O6) -> 281679
A8: Estoque | B8: 49774 | C8: =IFERROR(SUM((D8/B8)-1),0) -> 0.098545425 | D8: 54679 | E8: =IFERROR(SUM((F8/D8)-1),0) -> -0.10075166 | F8: 49170 | G8: =IFERROR(SUM((H8/F8)-1),0) -> -0.022696766 | H8: 48054 | J8: Patrimônio líq | K8: {=IFERROR(INDEX(Indicador_Ações[], MATCH($J$2, Indicador_Ações[Stock], 0), MATCH(Indicador_Ações[[#HEADERS],[patrimonio_liquido]], Indicador_Ações[#HEADERS], 0)),"")} -> 22159400000 | L8: {=IFERROR(INDEX(O7*K3,0)/L2,"")} -> 0.40049451 | M8: DPA Liquido | N8: Aliquota | O8: =ABS(SUM(B47,D47,F47,H47)/SUM(B46,D46,F46,H46)) -> 0.027844665
A9: Caixa | B9: 639620 | C9: =IFERROR(SUM((D9/B9)-1),0) -> -0.26722273 | D9: 468699 | E9: =IFERROR(SUM((F9/D9)-1),0) -> 0.53440908 | F9: 719176 | G9: =IFERROR(SUM((H9/F9)-1),0) -> 0.88557738 | H9: 1356062 | J9: Dívida bruta | K9: {=IFERROR(INDEX(Indicador_Ações[], MATCH($J$2, Indicador_Ações[Stock], 0), MATCH(Indicador_Ações[[#HEADERS],[divida_bruta]], Indicador_Ações[#HEADERS], 0)),"")} -> 17725700000 | L9: =IFERROR(L8/L7,0) -> 0.17347415 | M9: Payout_Ajustado | N9: NOPAT | O9: =K17*(1-O8) -> 1318090005
A10: Títulos e valores mobiliários | B10: 669456 | C10: =IFERROR(SUM((D10/B10)-1),0) -> 0.92479416 | D10: 1288565 | E10: =IFERROR(SUM((F10/D10)-1),0) -> 0.32006224 | F10: 1700986 | G10: =IFERROR(SUM((H10/F10)-1),0) -> -0.52443818 | H10: 808924 | J10: Dívida líq | K10: =K9-K7 -> 15968440000 | L10: =IFERROR(K14/K4,0) -> 0.21368317 | M10: GIRO ATIVOS
A11: Disponibilidades | B11: =SUM(B9,B10) -> 1309076 | C11: =IFERROR(SUM((D11/B11)-1),0) -> 0.34236973 | D11: =SUM(D9,D10) -> 1757264 | E11: =IFERROR(SUM((F11/D11)-1),0) -> 0.37723302 | F11: =SUM(F9,F10) -> 2420162 | G11: =IFERROR(SUM((H11/F11)-1),0) -> -0.10543757 | H11: =SUM(H9,H10) -> 2164986 | J11: Capital_Investido | K11: =SUM(K8,K9) -> 39885100000 | L11: =IFERROR(K24/K8,0) -> 0.12713205 | M11: ROE
J12: Razão de Divida | K12: =K9/K11 -> 0.44441909 | L12: =O9/K11 -> 0.033047178 | M12: ROIC
A13: Passivo Total | B13: =SUM(B14+B15) -> 20087970 | C13: =IFERROR(SUM((D13/B13)-1),0) -> 0.056154106 | D13: =SUM(D14+D15) -> 21215992 | E13: =IFERROR(SUM((F13/D13)-1),0) -> -0.12589975 | F13: =SUM(F14+F15) -> 18544904 | G13: =IFERROR(SUM((H13/F13)-1),0) -> 0.073316691 | H13: =SUM(H14+H15) -> 19904555 | J13: DRE | L13: =IFERROR(K24/K4,0) -> 0.056394381 | M13: ROA
A14: Passivo Circ. | B14: 1618504 | C14: =IFERROR(SUM((D14/B14)-1),0) -> -0.16030112 | D14: 1359056 | E14: =IFERROR(SUM((F14/D14)-1),0) -> 0.16557154 | F14: 1584077 | G14: =IFERROR(SUM((H14/F14)-1),0) -> 0.19128616 | H14: 1887089 | J14: Receita_IFRS | K14: {=IFERROR(INDEX(Indicador_Ações[], MATCH($J$2, Indicador_Ações[Stock], 0), MATCH(Indicador_Ações[[#HEADERS],[receita_liquida_12m]], Indicador_Ações[#HEADERS], 0)),"")} -> 10674500000 | L14: =K6/K18 -> 9.510342 | M14: EV/EBITDA
A15: Passivo Não Circ. | B15: 18469466 | C15: =IFERROR(SUM((D15/B15)-1),0) -> 0.075122367 | D15: 19856936 | E15: =IFERROR(SUM((F15/D15)-1),0) -> -0.14584874 | F15: 16960827 | G15: =IFERROR(SUM((H15/F15)-1),0) -> 0.06229879 | H15: 18017466 | J15: Receita REG | K15: =IFERROR(SUM(B32,D32,F32,H32),"")*K3 -> 4662787000 | L15: =K18/K6 -> 0.10514869 | M15: Earnings_Yield_Greenblatt
A16: Emprést. CP | B16: 390701 | C16: =IFERROR(SUM((D16/B16)-1),0) -> 0.13336285 | D16: 442806 | E16: =IFERROR(SUM((F16/D16)-1),0) -> -0.034931776 | F16: 427338 | G16: =IFERROR(SUM((H16/F16)-1),0) -> 0.3714741 | H16: 586083 | J16: Cagr_receita_5a | K16: {=IFERROR(INDEX(Indicador_Ações[], MATCH($J$2, Indicador_Ações[Stock], 0), MATCH(Indicador_Ações[[#HEADERS],[cagr_receita_5a]], Indicador_Ações[#HEADERS], 0)),"")} -> 17 | L16: =IFERROR(K10/K18,0) -> 4.2804577 | M16: DÍVIDA LÍQUIDA / EBITDA
A17: Emprést. LP | B17: 15855349 | C17: =IFERROR(SUM((D17/B17)-1),0) -> 0.087016628 | D17: 17235028 | E17: =IFERROR(SUM((F17/D17)-1),0) -> -0.16850103 | F17: 14330908 | G17: =IFERROR(SUM((H17/F17)-1),0) -> 0.072202124 | H17: 15365630 | J17: EBIT Reg | K17: =SUM(B42,D42,F42,H42)*K3 -> 1355843000 | L17: =IFERROR(SUM(B5,D5,F5,H5)/SUM(B14,D14,F14,H14),0) -> 1.8962814 | M17: LIQUIDEZ CORRENTE
J18: EBITDA Reg | K18: =IFERROR(SUM(B45,D45,F45,H45),"")*K3 -> 3730545000 | L18: =SUM(B42,D42,F42,H42)/ABS(SUM(B37,D37,F37,H37)) -> 0.64220647 | M18: Indice de Cobertura de Juros MEDIA
A19: ENDIVIDAMENTO / CAIXA | J19: Custo_Mercadoria | K19: =SUM(B31,D31,F31,H31)*K3 -> -715567000 | L19: =IFERROR(K4/K8,0) -> 2.254339 | M19: Alavancagem_Financeira
A20: Dívida bruta | B20: =SUM(B17,B16) -> 16246050 | C20: =IFERROR(SUM((D20/B20)-1),0) -> 0.088131207 | D20: =SUM(D17,D16) -> 17677834 | E20: =IFERROR(SUM((F20/D20)-1),0) -> -0.1651553 | F20: =SUM(F17,F16) -> 14758246 | G20: =IFERROR(SUM((H20/F20)-1),0) -> 0.080867808 | H20: =SUM(H17,H16) -> 15951713 | J20: Lucro bruto | K20: =IFERROR(SUM(B34,D34,F34,H34),"")*K3 -> 3125490000 | L20: =K10/K8 -> 0.72061698 | M20: DL/PL
A21: Dívida líq | B21: =SUM(B20-B11) -> 14936974 | C21: =IFERROR(SUM((D21/B21)-1),0) -> 0.06584975 | D21: =SUM(D20-D11) -> 15920570 | E21: =IFERROR(SUM((F21/D21)-1),0) -> -0.22502247 | F21: =SUM(F20-F11) -> 12338084 | G21: =IFERROR(SUM((H21/F21)-1),0) -> 0.11741231 | H21: =SUM(H20-H11) -> 13786727 | J21: Despesas operacionais REG | K21: =IFERROR(SUM(B33,D33,F33,H33),"")*K3 -> -1537297000 | M21: CPM
J22: Inflação | K22: ='Indicadores_Ações'!$B$4 -> 0.044430246 | L22: ='Indicadores_Ações'!$B$3 -> 0.139 | M22: RF
A23: Patrimônio líq. | B23: =B4-B13 -> 10616712 | C23: =IFERROR(SUM((D23/B23)-1),0) -> 0.014182545 | D23: =D4-D13 -> 10767284 | E23: =IFERROR(SUM((F23/D23)-1),0) -> -0.0080340595 | F23: =F4-F13 -> 10680779 | G23: =IFERROR(SUM((H23/F23)-1),0) -> -0.01799307 | H23: =H4-H13 -> 10488599 | J23: Lucro_Anual REG_Planilha | K23: =SUM(B48,D48,F48,H48)*K3 -> 1623752000 | L23: =K25 -> 0.81 | M23: Beta (B)
J24: Lucro_Liquido_Fundamentus | K24: {=IFERROR(INDEX(Indicador_Ações[], MATCH($J$2, Indicador_Ações[Stock], 0), MATCH(Indicador_Ações[[#HEADERS],[lucro_liquido_12m]], Indicador_Ações[#HEADERS], 0)),"")} -> 2817170000 | L24: =L22+0.02 -> 0.159 | M24: RM
A25: Reserva de Capital | B25: 666 | C25: =IFERROR(SUM((D25/B25)-1),0) -> 0 | D25: 666 | E25: =IFERROR(SUM((F25/D25)-1),0) -> 0 | F25: 666 | G25: =IFERROR(SUM((H25/F25)-1),0) -> 0 | H25: 666 | J25: Beta | K25: {=IFERROR(INDEX(Indicador_Ações[], MATCH($J$2, Indicador_Ações[Stock], 0), MATCH(Indicador_Ações[[#HEADERS],[beta_ibov_3a]], Indicador_Ações[#HEADERS], 0)),"")} -> 0.81 | L25: =L22+L23*(L24-L22) -> 0.1552 | M25: KE
A26: Reserva de Lucro | B26: 3859010 | C26: =IFERROR(SUM((D26/B26)-1),0) -> 0.05488247 | D26: 4070802 | E26: =IFERROR(SUM((F26/D26)-1),0) -> -0.055397438 | F26: 3845290 | G26: =IFERROR(SUM((H26/F26)-1),0) -> -0.026741546 | H26: 3742461
A28: DRE Analise Trimestral | J28: Ticker | K28: Valores | L28: Ano | M28: VLF | N28: VLP | O28: Cresc | Q28: Ano | R28: Fluxo
A29: Trimestre | B29: 1_T | C29: AH% (2/1) | D29: 2_T | E29: AH% (3/2) | F29: 3_T | G29: AH% (4/3) | H29: 4_T | J29: Preço_Mercado | K29: =K2 -> 27.74 | L29: 1 | M29: =K34 -> 1623752000 | O29: 10 | Q29: 0 | R29: =-K6 -> -35478758720
A30: Receita Operacional Bruta | B30: 1393479 | C30: =IFERROR(SUM((D30/B30)-1),0) -> 0.019869693 | D30: 1421167 | E30: =IFERROR(SUM((F30/D30)-1),0) -> -0.12003164 | F30: 1250582 | G30: =IFERROR(SUM((H30/F30)-1),0) -> 0.050011914 | H30: 1313126 | J30: Numero_Papel | K30: =L2 -> 703328000 | L30: 2 | M30: =M29*(1+O29/100) -> 1786127200 | N30: =M30/(1+K35)^L29 -> 1546162742 | O30: 10 | Q30: 1 | R30: =M30 -> 1786127200
A31: Deduções da receita Bruta | B31: -167215 | C31: =IFERROR(SUM((D31/B31)-1),0) -> 0.063259875 | D31: -177793 | E31: =IFERROR(SUM((F31/D31)-1),0) -> 0.0025647804 | F31: -178249 | G31: =IFERROR(SUM((H31/F31)-1),0) -> 0.078884033 | H31: -192310 | J31: Market | K31: =P21 | L31: 3 | M31: =M30*(1+O30/100) -> 1964739920 | N31: =M31/(1+K35)^L30 -> 1472281005 | O31: 10 | Q31: 2 | R31: =M31 -> 1964739920
A32: Receita Operacional Liquida | B32: =SUM(B30,B31) -> 1226264 | C32: =IFERROR(SUM((D32/B32)-1),0) -> 0.01395295 | D32: =SUM(D30,D31) -> 1243374 | E32: =IFERROR(SUM((F32/D32)-1),0) -> -0.13756199 | F32: =SUM(F30,F31) -> 1072333 | G32: =IFERROR(SUM((H32/F32)-1),0) -> 0.045212635 | H32: =SUM(H30,H31) -> 1120816 | J32: Taxa_Cresc | K32: =SUM(O29:O37)/6 -> 9.5 | L32: 4 | M32: =M31*(1+O31/100) -> 2161213912 | N32: =M32/(1+K35)^L31 -> 1401929627 | O32: 9 | Q32: 3 | R32: =M32 -> 2161213912
A33: Custos e Despesas | B33: -349209 | C33: =IFERROR(SUM((D33/B33)-1),0) -> 0.25040019 | D33: -436651 | E33: =IFERROR(SUM((F33/D33)-1),0) -> -0.18643264 | F33: -355245 | G33: =IFERROR(SUM((H33/F33)-1),0) -> 0.11526411 | H33: -396192 | J33: Taxa_Gordon | K33: 0.04 | L33: 5 | M33: =M32*(1+O32/100) -> 2355723164 | N33: =M33/(1+K35)^L32 -> 1322804098 | O33: 9 | Q33: 4 | R33: =M33 -> 2355723164
A34: Lucro Operacional Bruto | B34: =B32+B33 -> 877055 | C34: =IFERROR(SUM((D34/B34)-1),0) -> -0.080191094 | D34: =D32+D33 -> 806723 | E34: =IFERROR(SUM((F34/D34)-1),0) -> -0.11111001 | F34: =F32+F33 -> 717088 | G34: =IFERROR(SUM((H34/F34)-1),0) -> 0.01050917 | H34: =H32+H33 -> 724624 | J34: Receita_LL_REG | K34: =$K$23 -> 1623752000 | L34: 6 | M34: =M33*(1+O33/100) -> 2567738249 | N34: =M34/(1+K35)^L33 -> 1248144448 | O34: 9 | Q34: 5 | R34: =M34 -> 2567738249
J35: Taxa_desconto_KE | K35: =L25 -> 0.1552 | L35: 7 | M35: =M34*(1+O34/100) -> 2798834691 | N35: =M35/(1+K35)^L34 -> 1177698622 | Q35: 6 | R35: =M35+M36 -> 28066092321
A36: Receita Financeira | B36: 64291 | C36: =IFERROR(SUM((D36/B36)-1),0) -> -0.016207556 | D36: 63249 | E36: =IFERROR(SUM((F36/D36)-1),0) -> 0.60377239 | F36: 101437 | G36: =IFERROR(SUM((H36/F36)-1),0) -> 0.11006832 | H36: 112602 | J36: Valor_ação_Proj | K36: =K37/K30 -> 24.700599 | L36: Perpétuo | M36: =IFERROR( M35 * (1 + K33) / (K35 -K33 ), 0 ) -> 25267257629 | N36: =M36/(1+K35)^L35 -> 9203602363 | Q36: TIR | R36: =IFERROR(IRR(R29:R35),0) -> 0.017886036
A37: Despesa Financeira | B37: -547195 | C37: =IFERROR(SUM((D37/B37)-1),0) -> 0.28321348 | D37: -702168 | E37: =IFERROR(SUM((F37/D37)-1),0) -> -0.43806753 | F37: -394571 | G37: =IFERROR(SUM((H37/F37)-1),0) -> 0.18430397 | H37: -467292 | J37: Market_Proj | K37: =N37 -> 17372622905 | N37: =SUM(N29:N36) -> 17372622905
A38: Resultado Financeiro | B38: =B36+B37 -> -482904 | C38: =IFERROR(SUM((D38/B38)-1),0) -> 0.32307664 | D38: =D36+D37 -> -638919 | E38: =IFERROR(SUM((F38/D38)-1),0) -> -0.54120319 | F38: =F36+F37 -> -293134 | G38: =IFERROR(SUM((H38/F38)-1),0) -> 0.2099927 | H38: =H36+H37 -> -354690
A40: Resultado de equivalência patrimonial | B40: 83784 | C40: =IFERROR(SUM((D40/B40)-1),0) -> -0.053876635 | D40: 79270 | E40: =IFERROR(SUM((F40/D40)-1),0) -> 0.26611581 | F40: 100365 | G40: =IFERROR(SUM((H40/F40)-1),0) -> -0.11099487 | H40: 89225
A41: Outras Receitas/Despesas Operacionais | B41: -25391 | C41: =IFERROR(SUM((D41/B41)-1),0) -> 1.4379111 | D41: -61901 | E41: =IFERROR(SUM((F41/D41)-1),0) -> -1.0619215 | F41: 3833 | G41: =IFERROR(SUM((H41/F41)-1),0) -> -12.809027 | H41: -45264
A42: Lucro Operacional (EBIT)(LAJIR) | B42: =SUM(B34,B38) -> 394151 | C42: =IFERROR(SUM((D42/B42)-1),0) -> -0.57426469 | D42: =SUM(D34,D38) -> 167804 | E42: =IFERROR(SUM((F42/D42)-1),0) -> 1.5264833 | F42: =SUM(F34,F38) -> 423954 | G42: =IFERROR(SUM((H42/F42)-1),0) -> -0.12741948 | H42: =SUM(H34,H38) -> 369934
...

Sheet SAPR4
B1: Feito | C1: 46058 | D1: Atual | E1: 46247 | F1: Não | G1: 46058 | H1: Não | I1: 46058 | J1: Ultimo_Balanco | K1: {=IFERROR(INDEX(Indicador_Ações[], MATCH($J$2, Indicador_Ações[Stock], 0), MATCH(Indicador_Ações[[#HEADERS],[ult_balanco_processado]], Indicador_Ações[#HEADERS], 0)),"")} -> 46203
A2: Balanço Patrimonial Anual | J2: SAPR4 | K2: =IFERROR(__xludf.DUMMYFUNCTION("(GOOGLEFINANCE(""BVMF:"" & J2))"),6.83) -> 6.83 | L2: {=IFERROR(INDEX(Indicador_Ações[], MATCH($J$2, Indicador_Ações[Stock], 0), MATCH(Indicador_Ações[[#HEADERS],[qtd_acao]], Indicador_Ações[#HEADERS], 0)),"")} -> 1511210000 | M2: Numero_Papel
A3: Ano | B3: 1_T | C3: AH% (2/1) | D3: 2_T | E3: AH% (3/2) | F3: 3_T | G3: AH% (4/3) | H3: 4_T | J3: BP | K3: 1000 | L3: =IFERROR(K22/K14,0) -> 0.060356984 | M3: Margem_Liquida | N3: DMPL Acumulado
A4: Ativo Total | B4: =B5+B6 -> 26827910 | C4: =IFERROR(SUM((D4/B4)-1),0) -> -0.01100902 | D4: =D5+D6 -> 26532561 | E4: =IFERROR(SUM((F4/D4)-1),0) -> -0.019991285 | F4: =F5+F6 -> 26002141 | G4: =IFERROR(SUM((H4/F4)-1),0) -> 0.017836339 | H4: =H5+H6 -> 26465924 | J4: Ativo | K4: {=IFERROR(INDEX(Indicador_Ações[], MATCH($J$2, Indicador_Ações[Stock], 0), MATCH(Indicador_Ações[[#HEADERS],[ativo]], Indicador_Ações[#HEADERS], 0)),"")} -> 26532600000 | L4: =IFERROR(K19/K14,0) -> 0.53760275 | M4: MARGEM BRUTA | N4: JCP acionistas Liquido | O4: 91430
A5: Ativo Circulante | B5: 7025965 | C5: =IFERROR(SUM((D5/B5)-1),0) -> -0.099903003 | D5: 6324050 | E5: =IFERROR(SUM((F5/D5)-1),0) -> 0.18396328 | F5: 7487443 | G5: =IFERROR(SUM((H5/F5)-1),0) -> -0.03537643 | H5: 7222564 | J5: Valor_de_mercado | K5: =K2*L2 -> 10321564300 | L5: =IFERROR(K16/K14,0) -> 0.33712864 | M5: MARGEM EBIT | N5: Dividendos | O5: 0
A6: Ativo Nao Circ. | B6: 19801945 | C6: =IFERROR(SUM((D6/B6)-1),0) -> 0.020531619 | D6: 20208511 | E6: =IFERROR(SUM((F6/D6)-1),0) -> -0.083816814 | F6: 18514698 | G6: =IFERROR(SUM((H6/F6)-1),0) -> 0.039355867 | H6: 19243360 | J6: Valor_da_firma | K6: =SUM(K5,K10) -> 12909144300 | L6: =IFERROR(K17/K14,0) -> 0.39293364 | M6: MARGEM_EBITDA | N6: Dividendos e JCP | O6: =SUM(O4:O5) -> 91430
J7: Disponibilidade | K7: {=IFERROR(INDEX(Indicador_Ações[], MATCH($J$2, Indicador_Ações[Stock], 0), MATCH(Indicador_Ações[[#HEADERS],[disponibilidades]], Indicador_Ações[#HEADERS], 0)),"")} -> 4662450000 | L7: =K22/L2 -> 0.30124933 | M7: LPA | N7: Aliquota | O7: =ABS(SUM(B51,D51,F51,H51)/SUM(B50,D50,F50,H50)) -> 0.096882512
A8: Estoque | B8: 79524 | C8: =IFERROR(SUM((D8/B8)-1),0) -> 0.025250239 | D8: 81532 | E8: =IFERROR(SUM((F8/D8)-1),0) -> -0.053071187 | F8: 77205 | G8: =IFERROR(SUM((H8/F8)-1),0) -> 0.25643417 | H8: 97003 | J8: Patrimônio líq | K8: {=IFERROR(INDEX(Indicador_Ações[], MATCH($J$2, Indicador_Ações[Stock], 0), MATCH(Indicador_Ações[[#HEADERS],[patrimonio_liquido]], Indicador_Ações[#HEADERS], 0)),"")} -> 12103900000 | L8: {=IFERROR(INDEX(O6*K3,0)/L2,"")} -> 0.060501188 | M8: DPA Liquido | N8: NOPAT | O8: =K16*(1-O7) -> 2296483274
A9: Caixa | B9: 54662 | C9: =IFERROR(SUM((D9/B9)-1),0) -> 0.10420402 | D9: 60358 | E9: =IFERROR(SUM((F9/D9)-1),0) -> -0.50694191 | F9: 29760 | G9: =IFERROR(SUM((H9/F9)-1),0) -> -0.37153898 | H9: 18703 | J9: Dívida bruta | K9: {=IFERROR(INDEX(Indicador_Ações[], MATCH($J$2, Indicador_Ações[Stock], 0), MATCH(Indicador_Ações[[#HEADERS],[divida_bruta]], Indicador_Ações[#HEADERS], 0)),"")} -> 7250030000 | L9: =IFERROR(L8/L7,0) -> 0.20083427 | M9: Payout
A10: Títulos e valores mobiliários | B10: 5304820 | C10: =IFERROR(SUM((D10/B10)-1),0) -> -0.13246915 | D10: 4602095 | E10: =IFERROR(SUM((F10/D10)-1),0) -> 0.27121431 | F10: 5850249 | G10: =IFERROR(SUM((H10/F10)-1),0) -> -0.044582889 | H10: 5589428 | J10: Dívida líq | K10: =K9-K7 -> 2587580000 | L10: =IFERROR(K14/K4,0) -> 0.28427821 | M10: GIRO ATIVOS
A11: Disponibilidades | B11: =SUM(B9,B10) -> 5359482 | C11: =IFERROR(SUM((D11/B11)-1),0) -> -0.13005529 | D11: =SUM(D9,D10) -> 4662453 | E11: =IFERROR(SUM((F11/D11)-1),0) -> 0.26114065 | F11: =SUM(F9,F10) -> 5880009 | G11: =IFERROR(SUM((H11/F11)-1),0) -> -0.046237684 | H11: =SUM(H9,H10) -> 5608131 | J11: Capital_Investido | K11: =SUM(K8,K9) -> 19353930000 | L11: =IFERROR(K22/K8,0) -> 0.037611927 | M11: ROE
J12: Razão de Divida | K12: =K9/K11 -> 0.37460247 | L12: =O8/K11 -> 0.11865721 | M12: ROIC
A13: Passivo Total | B13: =SUM(B14+B15) -> 14127448 | C13: =IFERROR(SUM((D13/B13)-1),0) -> 0.021322889 | D13: =SUM(D14+D15) -> 14428686 | E13: =IFERROR(SUM((F13/D13)-1),0) -> -0.031690481 | F13: =SUM(F14+F15) -> 13971434 | G13: =IFERROR(SUM((H13/F13)-1),0) -> 0.01050064 | H13: =SUM(H14+H15) -> 14118143 | J13: DRE | L13: =IFERROR(K22/K4,0) -> 0.017158175 | M13: ROA
A14: Passivo Circ. | B14: 6491367 | C14: =IFERROR(SUM((D14/B14)-1),0) -> -0.47529111 | D14: 3406078 | E14: =IFERROR(SUM((F14/D14)-1),0) -> 0.72321421 | F14: 5869402 | G14: =IFERROR(SUM((H14/F14)-1),0) -> 0.026467092 | H14: 6024748 | J14: Receita_Liquida | K14: {=IFERROR(INDEX(Indicador_Ações[], MATCH($J$2, Indicador_Ações[Stock], 0), MATCH(Indicador_Ações[[#HEADERS],[receita_liquida_12m]], Indicador_Ações[#HEADERS], 0)),"")} -> 7542640000 | L14: =K6/K17 -> 4.3556689 | M14: EV/EBITDA
A15: Passivo Não Circ. | B15: 7636081 | C15: =IFERROR(SUM((D15/B15)-1),0) -> 0.44349019 | D15: 11022608 | E15: =IFERROR(SUM((F15/D15)-1),0) -> -0.26496234 | F15: 8102032 | G15: =IFERROR(SUM((H15/F15)-1),0) -> -0.0010660289 | H15: 8093395 | J15: Cagr_receita_5a | K15: {=IFERROR(INDEX(Indicador_Ações[], MATCH($J$2, Indicador_Ações[Stock], 0), MATCH(Indicador_Ações[[#HEADERS],[cagr_receita_5a]], Indicador_Ações[#HEADERS], 0)),"")} -> 8.5 | L15: =K17/K6 -> 0.22958586 | M15: Earnings_Yield_Greenblatt
A16: Emprést. CP | B16: 1369898 | C16: =IFERROR(SUM((D16/B16)-1),0) -> -0.089703759 | D16: 1247013 | E16: =IFERROR(SUM((F16/D16)-1),0) -> -0.24220598 | F16: 944979 | G16: =IFERROR(SUM((H16/F16)-1),0) -> 0.055398056 | H16: 997329 | J16: EBIT | K16: {=IFERROR(INDEX(Indicador_Ações[], MATCH($J$2, Indicador_Ações[Stock], 0), MATCH(Indicador_Ações[[#HEADERS],[ebit_12m]], Indicador_Ações[#HEADERS], 0)),"")} -> 2542840000 | L16: =IFERROR(K10/K17,0) -> 0.87307428 | M16: DÍVIDA LÍQUIDA / EBITDA Ajustado
A17: Emprést. LP | B17: 5910965 | C17: =IFERROR(SUM((D17/B17)-1),0) -> 0.015572753 | D17: 6003015 | E17: =IFERROR(SUM((F17/D17)-1),0) -> 0.051259409 | F17: 6310726 | G17: =IFERROR(SUM((H17/F17)-1),0) -> 0.013407174 | H17: 6395335 | J17: EBITDA | K17: =SUM(B49,D49,F49,H49)*K3 -> 2963757000 | L17: =IFERROR(SUM(B5,D5,F5,H5)/SUM(B14,D14,F14,H14),0) -> 1.2876534 | M17: LIQUIDEZ CORRENTE_Media
J18: Custo_Mercadoria | K18: =SUM(B32,D32,F32,H32)*K3 -> -3150783000 | L18: =SUM(B42,D42,F42,H42)/ABS(SUM(B45,D45,F45,H45)) -> 0.75895491 | M18: Indice de Cobertura de Juros MEDIA
A19: ENDIVIDAMENTO / CAIXA | J19: Lucro bruto | K19: =IFERROR(SUM(B33,D33,F33,H33),"")*K3 -> 4054944000 | L19: =IFERROR(K4/K8,0) -> 2.1920703 | M19: Alavancagem_Financeira
A20: Dívida bruta | B20: =SUM(B17,B16) -> 7280863 | C20: =IFERROR(SUM((D20/B20)-1),0) -> -0.0042350749 | D20: =SUM(D17,D16) -> 7250028 | E20: =IFERROR(SUM((F20/D20)-1),0) -> 0.00078303146 | F20: =SUM(F17,F16) -> 7255705 | G20: =IFERROR(SUM((H20/F20)-1),0) -> 0.018876043 | H20: =SUM(H17,H16) -> 7392664 | J20: Despesas operacionais | K20: =IFERROR(SUM(B32,D32,F32,H32),"")*K3 -> -3150783000 | L20: =K10/K8 -> 0.21378068 | M20: DL/PL
A21: Dívida líq | B21: =SUM(B20-B11) -> 1921381 | C21: =IFERROR(SUM((D21/B21)-1),0) -> 0.34672665 | D21: =SUM(D20-D11) -> 2587575 | E21: =IFERROR(SUM((F21/D21)-1),0) -> -0.46834546 | F21: =SUM(F20-F11) -> 1375696 | G21: =IFERROR(SUM((H21/F21)-1),0) -> 0.29718557 | H21: =SUM(H20-H11) -> 1784533 | J21: Inflação | K21: ='Indicadores_Ações'!$B$4 -> 0.044430246 | M21: CPM
J22: Lucro_Liquido_Fundamentus | K22: {=IFERROR(INDEX(Indicador_Ações[], MATCH($J$2, Indicador_Ações[Stock], 0), MATCH(Indicador_Ações[[#HEADERS],[lucro_liquido_12m]], Indicador_Ações[#HEADERS], 0)),"")} -> 455251000 | L22: ='Indicadores_Ações'!$B$3 -> 0.139 | M22: RF
A23: Patrimônio líq. | B23: =B4-B13 -> 12700462 | C23: =IFERROR(SUM((D23/B23)-1),0) -> -0.046973646 | D23: =D4-D13 -> 12103875 | E23: =IFERROR(SUM((F23/D23)-1),0) -> -0.0060450062 | F23: =F4-F13 -> 12030707 | G23: =IFERROR(SUM((H23/F23)-1),0) -> 0.026355392 | H23: =H4-H13 -> 12347781 | J23: Lucro_Planilha | K23: =SUM(B52,D52,F52,H52)*K3 -> 2079568000 | L23: =K24 -> 0.73 | M23: Beta (B)
J24: Beta | K24: {=IFERROR(INDEX(Indicador_Ações[], MATCH($J$2, Indicador_Ações[Stock], 0), MATCH(Indicador_Ações[[#HEADERS],[beta_ibov_3a]], Indicador_Ações[#HEADERS], 0)),"")} -> 0.73 | L24: =L22+0.02 -> 0.159 | M24: RM
A25: Reserva de Capital | B25: 0 | C25: =IFERROR(SUM((D25/B25)-1),0) -> 0 | D25: 0 | E25: =IFERROR(SUM((F25/D25)-1),0) -> 0 | F25: 0 | G25: =IFERROR(SUM((H25/F25)-1),0) -> 0 | H25: 0 | L25: =L22+L23*(L24-L22) -> 0.1536 | M25: KE
A26: Reserva de Lucro | B26: 6088560 | C26: =IFERROR(SUM((D26/B26)-1),0) -> -0.015016687 | D26: 5997130 | E26: =IFERROR(SUM((F26/D26)-1),0) -> -0.24983467 | F26: 4498839 | G26: =IFERROR(SUM((H26/F26)-1),0) -> 0.3533625 | H26: 6088560
A27: Lucro ou Prejuizo Acumulados | B27: 353621 | C27: =IFERROR(SUM((D27/B27)-1),0) -> -1.4258486 | D27: -150589 | E27: =IFERROR(SUM((F27/D27)-1),0) -> -9.6386456 | F27: 1300885 | G27: =IFERROR(SUM((H27/F27)-1),0) -> -1 | H27: 0 | J27: Ticker | K27: Valores | L27: Ano | M27: VLF | N27: VLP | O27: Cresc | Q27: Ano | R27: Fluxo
J28: Preço_Mercado | K28: =K2 -> 6.83 | L28: 1 | M28: =K33 -> 1180945000 | O28: 6 | Q28: 0 | R28: =-K6 -> -12909144300
A29: DRE Analise Trimestral | J29: Numero_Papel | K29: =L2 -> 1511210000 | L29: 2 | M29: =M28*(1+O28/100) -> 1251801700 | N29: =M29/(1+K34)^L28 -> 1085126300 | O29: 6 | Q29: 1 | R29: =M29 -> 1251801700
A30: Trimestre | B30: 1_T | C30: AH% (2/1) | D30: 2_T | E30: AH% (3/2) | F30: 3_T | G30: AH% (4/3) | H30: 4_T | J30: Market | K30: =K5 -> 10321564300 | L30: 3 | M30: =M29*(1+O29/100) -> 1326909802 | N30: =M30/(1+K34)^L29 -> 997082072 | O30: 6 | Q30: 2 | R30: =M30 -> 1326909802
A31: Receita Liquida | B31: 1946354 | C31: =IFERROR(SUM((D31/B31)-1),0) -> -0.023219825 | D31: 1901160 | E31: =IFERROR(SUM((F31/D31)-1),0) -> -0.051015696 | F31: 1804171 | G31: =IFERROR(SUM((H31/F31)-1),0) -> -0.1386393 | H31: =IFERROR(B83- SUM(B31,D31,F31),"") -> 1554042 | J31: Taxa_Cresc | K31: =SUM(O28:O36)/6 -> 6 | L31: 4 | M31: =M30*(1+O30/100) -> 1406524390 | N31: =M31/(1+K34)^L30 -> 9.1618152e+08 | O31: 6 | Q31: 3 | R31: =M31 -> 1406524390
A32: Custo Mercadoria (CMV) | B32: -789461 | C32: =IFERROR(SUM((D32/B32)-1),0) -> 0.050929685 | D32: -829668 | E32: =IFERROR(SUM((F32/D32)-1),0) -> -0.052455922 | F32: -786147 | G32: =IFERROR(SUM((H32/F32)-1),0) -> -0.051695166 | H32: =IFERROR(B84- SUM(B32,D32,F32),"") -> -745507 | J32: Taxa_Gordon | K32: 0.04 | L32: 5 | M32: =M31*(1+O31/100) -> 1490915854 | N32: =M32/(1+K34)^L31 -> 8.4184501e+08 | O32: 6 | Q32: 4 | R32: =M32 -> 1490915854
A33: Lucro Bruto | B33: =B31+B32 -> 1156893 | C33: =IFERROR(SUM((D33/B33)-1),0) -> -0.073819273 | D33: =D31+D32 -> 1071492 | E33: =IFERROR(SUM((F33/D33)-1),0) -> -0.049900513 | F33: =F31+F32 -> 1018024 | G33: =IFERROR(SUM((H33/F33)-1),0) -> -0.20578002 | H33: =H31+H32 -> 808535 | J33: Lucro_Ajustado_Planilha | K33: =L46 -> 1180945000 | L33: 6 | M33: =M32*(1+O32/100) -> 1580370805 | N33: =M33/(1+K34)^L32 -> 7.7353997e+08 | O33: 6 | Q33: 5 | R33: =M33 -> 1580370805
A34: DESPESAS E OUTRAS RECEITAS | J34: Taxa_desconto_KE | K34: =L25 -> 0.1536 | L34: 7 | M34: =M33*(1+O33/100) -> 1675193053 | N34: =M34/(1+K34)^L33 -> 7.1077702e+08 | Q34: 6 | R34: =M34+M35 -> 17011467482
A35: Despesas com Vendas | B35: -138018 | C35: =IFERROR(SUM((D35/B35)-1),0) -> 0.12220145 | D35: -154884 | E35: =IFERROR(SUM((F35/D35)-1),0) -> -0.16647943 | F35: -129099 | G35: =IFERROR(SUM((H35/F35)-1),0) -> 1.2002262 | H35: =IFERROR(B87- SUM(B35,D35,F35),"") -> -284047 | J35: Valor_ação_Proj | K35: =K36/K29 -> 7.255943 | L35: Perpétuo | M35: =IFERROR( M34 * (1 + K32) / (K34 -K32 ), 0 ) -> 15336274429 | N35: =M35/(1+K34)^L34 -> 5640701782 | Q35: TIR | R35: =IFERROR(IRR(R28:R34),0) -> 0.13281138
A36: Despesa Administrativa | B36: -287230 | C36: =IFERROR(SUM((D36/B36)-1),0) -> 0.019357309 | D36: -292790 | E36: =IFERROR(SUM((F36/D36)-1),0) -> -0.023443424 | F36: -285926 | G36: =IFERROR(SUM((H36/F36)-1),0) -> 0.81354966 | H36: =IFERROR(B88- SUM(B36,D36,F36),"") -> -518541 | J36: Market_Proj | K36: =N36 -> 10965253677 | N36: =SUM(N28:N35) -> 10965253677
A37: Despesa Administrativa (%) | B37: =ABS(B36)/B31 -> 0.14757336 | C37: =IFERROR(SUM((D37/B37)-1),0) -> 0.04358927 | D37: =ABS(D36)/D31 -> 0.15400598 | E37: =IFERROR(SUM((F37/D37)-1),0) -> 0.029054508 | F37: =ABS(F36)/F31 -> 0.15848054 | G37: =IFERROR(SUM((H37/F37)-1),0) -> 1.1054474 | H37: =ABS(H36)/H31 -> 0.33367245
A38: Outras receitas | B38: 746 | C38: =IFERROR(SUM((D38/B38)-1),0) -> 3.4651475 | D38: 3331 | E38: =IFERROR(SUM((F38/D38)-1),0) -> -0.64755329 | F38: 1174 | G38: =IFERROR(SUM((H38/F38)-1),0) -> 1759.2879 | H38: =IFERROR(B90- SUM(B38,D38,F38),"") -> 2066578
A39: Outras despesas | B39: -61349 | C39: =IFERROR(SUM((D39/B39)-1),0) -> 3.2664265 | D39: -261741 | E39: =IFERROR(SUM((F39/D39)-1),0) -> -0.22247183 | F39: -203511 | G39: =IFERROR(SUM((H39/F39)-1),0) -> 4.7158974 | H39: =IFERROR(B91- SUM(B39,D39,F39),"") -> -1163248
A40: Perdas Não Recuperabilidade de Ativos | B40: 0 | C40: =IFERROR(SUM((D40/B40)-1),0) -> 0 | D40: 0 | E40: =IFERROR(SUM((F40/D40)-1),0) -> 0 | F40: 0 | G40: =IFERROR(SUM((H40/F40)-1),0) -> 0 | H40: =IFERROR(B92- SUM(B40,D40,F40),"") -> -8883
...

Sheet WEGE3
B1: Feito | C1: 46058 | D1: Atual | E1: 46225 | F1: Não | G1: 46058 | H1: Não | I1: 46058 | J1: Ultimo_Balanco | K1: {=IFERROR(INDEX(Indicador_Ações[], MATCH($J$2, Indicador_Ações[Stock], 0), MATCH(Indicador_Ações[[#HEADERS],[ult_balanco_processado]], Indicador_Ações[#HEADERS], 0)),"")} -> 46203
A2: Balanço Patrimonial Anual | J2: WEGE3 | K2: =IFERROR(__xludf.DUMMYFUNCTION("(GOOGLEFINANCE(""BVMF:"" & J2))"),51.79) -> 51.79 | L2: {=IFERROR(INDEX(Indicador_Ações[], MATCH($J$2, Indicador_Ações[Stock], 0), MATCH(Indicador_Ações[[#HEADERS],[qtd_acao]], Indicador_Ações[#HEADERS], 0)),"")} -> 4197320000 | M2: Numero_Papel
A3: Ano | B3: 1_T | C3: AH% (2/1) | D3: 2_T | E3: AH% (3/2) | F3: 3_T | G3: AH% (4/3) | H3: 4_T | J3: BP | K3: 1000 | L3: =IFERROR(K22/K14,0) -> 0.15584398 | M3: Margem_Liquida | N3: DMPL Acumulado
A4: Ativo Total | B4: =B5+B6 -> 43377646 | C4: =IFERROR(SUM((D4/B4)-1),0) -> 0.075817507 | D4: =D5+D6 -> 46666431 | E4: =IFERROR(SUM((F4/D4)-1),0) -> -0.11082819 | F4: =F5+F6 -> 41494475 | G4: =IFERROR(SUM((H4/F4)-1),0) -> 0.027727908 | H4: =H5+H6 -> 42645030 | J4: Ativo | K4: {=IFERROR(INDEX(Indicador_Ações[], MATCH($J$2, Indicador_Ações[Stock], 0), MATCH(Indicador_Ações[[#HEADERS],[ativo]], Indicador_Ações[#HEADERS], 0)),"")} -> 46666400000 | L4: =IFERROR(K19/K14,0) -> 0.34093109 | M4: MARGEM BRUTA | N4: JCP acionistas Liquido | O4: 91430
A5: Ativo Circulante | B5: 27341315 | C5: =IFERROR(SUM((D5/B5)-1),0) -> 0.099256821 | D5: 30055127 | E5: =IFERROR(SUM((F5/D5)-1),0) -> -0.10909906 | F5: 26776141 | G5: =IFERROR(SUM((H5/F5)-1),0) -> 0.0050307473 | H5: 26910845 | J5: Valor_de_mercado | K5: =K2*L2 -> 217379202800 | L5: =IFERROR(K16/K14,0) -> 0.20931942 | M5: MARGEM EBIT | N5: Dividendos | O5: 0
A6: Ativo Nao Circ. | B6: 16036331 | C6: =IFERROR(SUM((D6/B6)-1),0) -> 0.035854398 | D6: 16611304 | E6: =IFERROR(SUM((F6/D6)-1),0) -> -0.11395674 | F6: 14718334 | G6: =IFERROR(SUM((H6/F6)-1),0) -> 0.069019428 | H6: 15734185 | J6: Valor_da_firma | K6: =SUM(K5,K10) -> 213644412800 | L6: =IFERROR(K17/K14,0) -> 0.22427095 | M6: MARGEM_EBITDA | N6: Dividendos e JCP | O6: =SUM(O4:O5) -> 91430
J7: Disponibilidade | K7: {=IFERROR(INDEX(Indicador_Ações[], MATCH($J$2, Indicador_Ações[Stock], 0), MATCH(Indicador_Ações[[#HEADERS],[disponibilidades]], Indicador_Ações[#HEADERS], 0)),"")} -> 8801140000 | L7: =K22/L2 -> 1.4900103 | M7: LPA | N7: Aliquota | O7: =ABS(SUM(B52,D52,F52,H52)/SUM(B51,D51,F51,H51)) -> 0.16835707
A8: Estoque | B8: 10027505 | C8: =IFERROR(SUM((D8/B8)-1),0) -> 0.067874112 | D8: 10708113 | E8: =IFERROR(SUM((F8/D8)-1),0) -> -0.066916552 | F8: 9991563 | G8: =IFERROR(SUM((H8/F8)-1),0) -> -0.0080577984 | H8: 9911053 | J8: Patrimônio líq | K8: {=IFERROR(INDEX(Indicador_Ações[], MATCH($J$2, Indicador_Ações[Stock], 0), MATCH(Indicador_Ações[[#HEADERS],[patrimonio_liquido]], Indicador_Ações[#HEADERS], 0)),"")} -> 18861400000 | L8: {=IFERROR(INDEX(O6*K3,0)/L2,"")} -> 0.021782947 | M8: DPA Liquido | N8: NOPAT | O8: =K16*(1-O7) -> 6985825589
A9: Caixa | B9: 6360547 | C9: =IFERROR(SUM((D9/B9)-1),0) -> 0.21848891 | D9: 7750256 | E9: =IFERROR(SUM((F9/D9)-1),0) -> -0.17208064 | F9: 6416587 | G9: =IFERROR(SUM((H9/F9)-1),0) -> -0.018715401 | H9: 6296498 | J9: Dívida bruta | K9: {=IFERROR(INDEX(Indicador_Ações[], MATCH($J$2, Indicador_Ações[Stock], 0), MATCH(Indicador_Ações[[#HEADERS],[divida_bruta]], Indicador_Ações[#HEADERS], 0)),"")} -> 5066350000 | L9: =IFERROR(L8/L7,0) -> 0.014619327 | M9: Payout
A10: Títulos e valores mobiliários | B10: 1025221 | C10: =IFERROR(SUM((D10/B10)-1),0) -> 0.025033627 | D10: 1050886 | E10: =IFERROR(SUM((F10/D10)-1),0) -> -0.12576245 | F10: 918724 | G10: =IFERROR(SUM((H10/F10)-1),0) -> 0.070361719 | H10: 983367 | J10: Dívida líq | K10: =K9-K7 -> -3734790000 | L10: =IFERROR(K14/K4,0) -> 0.85993777 | M10: GIRO ATIVOS
A11: Disponibilidades | B11: =SUM(B9,B10) -> 7385768 | C11: =IFERROR(SUM((D11/B11)-1),0) -> 0.19163532 | D11: =SUM(D9,D10) -> 8801142 | E11: =IFERROR(SUM((F11/D11)-1),0) -> -0.16655009 | F11: =SUM(F9,F10) -> 7335311 | G11: =IFERROR(SUM((H11/F11)-1),0) -> -0.0075587797 | H11: =SUM(H9,H10) -> 7279865 | J11: Capital_Investido | K11: =SUM(K8,K9) -> 23927750000 | L11: =IFERROR(K22/K8,0) -> 0.33157931 | M11: ROE
J12: Razão de Divida | K12: =K9/K11 -> 0.21173533 | L12: =O8/K11 -> 0.29195497 | M12: ROIC
A13: Passivo Total | B13: =SUM(B14+B15) -> 24294017 | C13: =IFERROR(SUM((D13/B13)-1),0) -> 0.089776014 | D13: =SUM(D14+D15) -> 26475037 | E13: =IFERROR(SUM((F13/D13)-1),0) -> -0.31717164 | F13: =SUM(F14+F15) -> 18077906 | G13: =IFERROR(SUM((H13/F13)-1),0) -> 0.332658 | H13: =SUM(H14+H15) -> 24091666 | J13: DRE | L13: =IFERROR(K22/K4,0) -> 0.13401612 | M13: ROA
A14: Passivo Circ. | B14: 17662876 | C14: =IFERROR(SUM((D14/B14)-1),0) -> 0.071493567 | D14: 18925658 | E14: =IFERROR(SUM((F14/D14)-1),0) -> -0.2045298 | F14: 15054797 | G14: =IFERROR(SUM((H14/F14)-1),0) -> 0.15487449 | H14: 17386401 | J14: Receita_Liquida | K14: {=IFERROR(INDEX(Indicador_Ações[], MATCH($J$2, Indicador_Ações[Stock], 0), MATCH(Indicador_Ações[[#HEADERS],[receita_liquida_12m]], Indicador_Ações[#HEADERS], 0)),"")} -> 40130200000 | L14: =K6/K17 -> 23.738168 | M14: EV/EBITDA
A15: Passivo Não Circ. | B15: 6631141 | C15: =IFERROR(SUM((D15/B15)-1),0) -> 0.13847361 | D15: 7549379 | E15: =IFERROR(SUM((F15/D15)-1),0) -> -0.59955527 | F15: 3023109 | G15: =IFERROR(SUM((H15/F15)-1),0) -> 1.2180031 | H15: 6705265 | J15: Cagr_receita_5a | K15: {=IFERROR(INDEX(Indicador_Ações[], MATCH($J$2, Indicador_Ações[Stock], 0), MATCH(Indicador_Ações[[#HEADERS],[cagr_receita_5a]], Indicador_Ações[#HEADERS], 0)),"")} -> 11.2 | L15: =K17/K6 -> 0.04212625 | M15: Earnings_Yield_Greenblatt
